Workbook

Sheet Portada
B2: BASE DE DATOS TÉCNICA — SISTEMA CCTV INTEGRAL
B3: Plantilla editable · 20 marcas · 14 tipos de cámara · 5 variantes por tipo · 10 categorías de equipamiento · Precios en USD
B5: 20 | C5: 14 | D5: =COUNTA('Base de Datos'!$G$5:$G$972) -> 968 | E5: =COUNTIFS('Base de Datos'!$G$5:$G$972,"<>*No disponible*") -> 860 | F5: 10 | G5: =COUNTA(Equipamiento!$F$5:$F$66) -> 62
B6: Marcas | C6: Tipos de cámara | D6: Modelos de cámara | E6: Cámaras activas | F6: Categorías de equipo | G6: Equipos registrados
B9: Hoja | C9: Contenido
B10: =HYPERLINK("#'Resumen'!B2","Resumen") -> Resumen | C10: Cobertura marca × tipo, estadísticas de cámaras y equipamiento
B11: =HYPERLINK("#'Base de Datos'!B2","Base de Datos") -> Base de Datos | C11: Hoja maestra: 968 registros (5 variantes por tipo y marca) filtrables
B12: =HYPERLINK("#'Equipamiento'!B2","Equipamiento") -> Equipamiento | C12: NVR/DVR, HDD, switch PoE, UPS, monitores, rack, cableado, accesorios, fuentes y VMS
B13: =HYPERLINK("#'Comparativa'!B2","Comparativa") -> Comparativa | C13: Ficha comparativa por tipo (modelo premium / medio / económico)
B14: =HYPERLINK("#'Lista de Precios'!B2","Lista de Precios") -> Lista de Precios | C14: Cotización integral: sección A cámaras + sección B equipamiento
B15: Niveles de marca incluidos
B16: Nivel | C16: Marcas | D16: Enfoque
B17: Premium | C17: Axis, Bosch, Hanwha Vision, Avigilon, Pelco, Honeywell, MOBOTIX | D17: Máxima calidad óptica, analíticas y soporte; precio alto
B18: Premium (Cloud) / Medio-Alto | C18: Verkada · Vivotek, IDIS | D18: Gestión en la nube o gama profesional intermedia
B19: Medio | C19: Hikvision, Dahua, Uniview, Ubiquiti (UniFi Protect) | D19: La mejor relación precio/rendimiento del mercado
B20: Económico | C20: HiLook, Imou, EZVIZ, Reolink, TP-Link VIGI, Tenda | D20: Proyectos de bajo presupuesto; matrículas de las matrices Hikvision/Dahua
B23: Notas de uso
B24: 1. Las especificaciones y precios son referenciales (USD, mercado 2026); verifique siempre la ficha técnica vigente del fabricante antes de cotizar o instalar.
B25: 2. Filas «No disponible en portafolio» (marcadas en ámbar): la marca no fabrica ese tipo de cámara; en Observaciones se sugiere el equivalente de su matriz u otra marca.
B26: 3. Use los filtros de la fila de encabezados en Base de Datos (panel congelado en H5) y en Equipamiento (panel congelado en G5) para segmentar por marca, categoría, nivel o precio.
B27: 4. Hoja Equipamiento: NVR/DVR, discos de vigilancia, switch PoE, UPS, monitores, rack, cableado, accesorios, fuentes/PoE y software VMS (62 modelos de referencia).
B28: 5. En Lista de Precios, complete Cantidad y Descuento en ambas secciones (A cámaras / B equipamiento); los subtotales y el TOTAL GENERAL se calculan automáticamente.
B29: 6. Las columnas Proveedor y Stock están listas para registrar sus distribuidores locales (con listas desplegables en Categoría, Nivel, Stock y Uso).
B30: 7. Hoja Comparativa: fichas de los 14 tipos de cámara con un modelo de referencia por nivel (premium / medio / económico).

Sheet Resumen
B2: Resumen — Cobertura Marca × Tipo y Estadísticas de Equipamiento
B5: Tipo de Cámara \ Marca | C5: Axis Communications | D5: Bosch Security Systems | E5: Hanwha Vision (Wisenet) | F5: Avigilon (Motorola) | G5: Pelco (Motorola) | H5: Honeywell Security | I5: MOBOTIX | J5: Vivotek | K5: IDIS | L5: Verkada | M5: Ubiquiti (UniFi Protect) | N5: Hikvision | O5: Dahua Technology | P5: Uniview (UNV) | Q5: HiLook (Hikvision) | R5: Imou (Dahua) | S5: EZVIZ (Hikvision) | T5: Reolink | U5: TP-Link VIGI | V5: Tenda Security | W5: Total
B6: Domo | C6: =COUNTIFS('Base de Datos'!$C$5:$C$972,C$5,'Base de Datos'!$F$5:$F$972,$B6,'Base de Datos'!$G$5:$G$972,"<>*No disponible*") -> 5 | D6: =COUNTIFS('Base de Datos'!$C$5:$C$972,D$5,'Base de Datos'!$F$5:$F$972,$B6,'Base de Datos'!$G$5:$G$972,"<>*No disponible*") -> 5 | E6: =COUNTIFS('Base de Datos'!$C$5:$C$972,E$5,'Base de Datos'!$F$5:$F$972,$B6,'Base de Datos'!$G$5:$G$972,"<>*No disponible*") -> 5 | F6: =COUNTIFS('Base de Datos'!$C$5:$C$972,F$5,'Base de Datos'!$F$5:$F$972,$B6,'Base de Datos'!$G$5:$G$972,"<>*No disponible*") -> 5 | G6: =COUNTIFS('Base de Datos'!$C$5:$C$972,G$5,'Base de Datos'!$F$5:$F$972,$B6,'Base de Datos'!$G$5:$G$972,"<>*No disponible*") -> 5 | H6: =COUNTIFS('Base de Datos'!$C$5:$C$972,H$5,'Base de Datos'!$F$5:$F$972,$B6,'Base de Datos'!$G$5:$G$972,"<>*No disponible*") -> 5 | I6: =COUNTIFS('Base de Datos'!$C$5:$C$972,I$5,'Base de Datos'!$F$5:$F$972,$B6,'Base de Datos'!$G$5:$G$972,"<>*No disponible*") -> 5 | J6: =COUNTIFS('Base de Datos'!$C$5:$C$972,J$5,'Base de Datos'!$F$5:$F$972,$B6,'Base de Datos'!$G$5:$G$972,"<>*No disponible*") -> 5 | ... V6: =COUNTIFS('Base de Datos'!$C$5:$C$972,V$5,'Base de Datos'!$F$5:$F$972,$B6,'Base de Datos'!$G$5:$G$972,"<>*No disponible*") -> 5 | W6: =SUM(C6:V6) -> 100
B7: Domo Antivandálica | C7: =COUNTIFS('Base de Datos'!$C$5:$C$972,C$5,'Base de Datos'!$F$5:$F$972,$B7,'Base de Datos'!$G$5:$G$972,"<>*No disponible*") -> 5 | D7: =COUNTIFS('Base de Datos'!$C$5:$C$972,D$5,'Base de Datos'!$F$5:$F$972,$B7,'Base de Datos'!$G$5:$G$972,"<>*No disponible*") -> 5 | E7: =COUNTIFS('Base de Datos'!$C$5:$C$972,E$5,'Base de Datos'!$F$5:$F$972,$B7,'Base de Datos'!$G$5:$G$972,"<>*No disponible*") -> 5 | F7: =COUNTIFS('Base de Datos'!$C$5:$C$972,F$5,'Base de Datos'!$F$5:$F$972,$B7,'Base de Datos'!$G$5:$G$972,"<>*No disponible*") -> 5 | G7: =COUNTIFS('Base de Datos'!$C$5:$C$972,G$5,'Base de Datos'!$F$5:$F$972,$B7,'Base de Datos'!$G$5:$G$972,"<>*No disponible*") -> 5 | H7: =COUNTIFS('Base de Datos'!$C$5:$C$972,H$5,'Base de Datos'!$F$5:$F$972,$B7,'Base de Datos'!$G$5:$G$972,"<>*No disponible*") -> 5 | I7: =COUNTIFS('Base de Datos'!$C$5:$C$972,I$5,'Base de Datos'!$F$5:$F$972,$B7,'Base de Datos'!$G$5:$G$972,"<>*No disponible*") -> 5 | J7: =COUNTIFS('Base de Datos'!$C$5:$C$972,J$5,'Base de Datos'!$F$5:$F$972,$B7,'Base de Datos'!$G$5:$G$972,"<>*No disponible*") -> 5 | ... V7: =COUNTIFS('Base de Datos'!$C$5:$C$972,V$5,'Base de Datos'!$F$5:$F$972,$B7,'Base de Datos'!$G$5:$G$972,"<>*No disponible*") -> 0 | W7: =SUM(C7:V7) -> 80
B8: Bala | C8: =COUNTIFS('Base de Datos'!$C$5:$C$972,C$5,'Base de Datos'!$F$5:$F$972,$B8,'Base de Datos'!$G$5:$G$972,"<>*No disponible*") -> 5 | D8: =COUNTIFS('Base de Datos'!$C$5:$C$972,D$5,'Base de Datos'!$F$5:$F$972,$B8,'Base de Datos'!$G$5:$G$972,"<>*No disponible*") -> 5 | E8: =COUNTIFS('Base de Datos'!$C$5:$C$972,E$5,'Base de Datos'!$F$5:$F$972,$B8,'Base de Datos'!$G$5:$G$972,"<>*No disponible*") -> 5 | F8: =COUNTIFS('Base de Datos'!$C$5:$C$972,F$5,'Base de Datos'!$F$5:$F$972,$B8,'Base de Datos'!$G$5:$G$972,"<>*No disponible*") -> 5 | G8: =COUNTIFS('Base de Datos'!$C$5:$C$972,G$5,'Base de Datos'!$F$5:$F$972,$B8,'Base de Datos'!$G$5:$G$972,"<>*No disponible*") -> 5 | H8: =COUNTIFS('Base de Datos'!$C$5:$C$972,H$5,'Base de Datos'!$F$5:$F$972,$B8,'Base de Datos'!$G$5:$G$972,"<>*No disponible*") -> 5 | I8: =COUNTIFS('Base de Datos'!$C$5:$C$972,I$5,'Base de Datos'!$F$5:$F$972,$B8,'Base de Datos'!$G$5:$G$972,"<>*No disponible*") -> 5 | J8: =COUNTIFS('Base de Datos'!$C$5:$C$972,J$5,'Base de Datos'!$F$5:$F$972,$B8,'Base de Datos'!$G$5:$G$972,"<>*No disponible*") -> 5 | ... V8: =COUNTIFS('Base de Datos'!$C$5:$C$972,V$5,'Base de Datos'!$F$5:$F$972,$B8,'Base de Datos'!$G$5:$G$972,"<>*No disponible*") -> 5 | W8: =SUM(C8:V8) -> 100
B9: PTZ | C9: =COUNTIFS('Base de Datos'!$C$5:$C$972,C$5,'Base de Datos'!$F$5:$F$972,$B9,'Base de Datos'!$G$5:$G$972,"<>*No disponible*") -> 5 | D9: =COUNTIFS('Base de Datos'!$C$5:$C$972,D$5,'Base de Datos'!$F$5:$F$972,$B9,'Base de Datos'!$G$5:$G$972,"<>*No disponible*") -> 5 | E9: =COUNTIFS('Base de Datos'!$C$5:$C$972,E$5,'Base de Datos'!$F$5:$F$972,$B9,'Base de Datos'!$G$5:$G$972,"<>*No disponible*") -> 5 | F9: =COUNTIFS('Base de Datos'!$C$5:$C$972,F$5,'Base de Datos'!$F$5:$F$972,$B9,'Base de Datos'!$G$5:$G$972,"<>*No disponible*") -> 5 | G9: =COUNTIFS('Base de Datos'!$C$5:$C$972,G$5,'Base de Datos'!$F$5:$F$972,$B9,'Base de Datos'!$G$5:$G$972,"<>*No disponible*") -> 5 | H9: =COUNTIFS('Base de Datos'!$C$5:$C$972,H$5,'Base de Datos'!$F$5:$F$972,$B9,'Base de Datos'!$G$5:$G$972,"<>*No disponible*") -> 5 | I9: =COUNTIFS('Base de Datos'!$C$5:$C$972,I$5,'Base de Datos'!$F$5:$F$972,$B9,'Base de Datos'!$G$5:$G$972,"<>*No disponible*") -> 5 | J9: =COUNTIFS('Base de Datos'!$C$5:$C$972,J$5,'Base de Datos'!$F$5:$F$972,$B9,'Base de Datos'!$G$5:$G$972,"<>*No disponible*") -> 5 | ... V9: =COUNTIFS('Base de Datos'!$C$5:$C$972,V$5,'Base de Datos'!$F$5:$F$972,$B9,'Base de Datos'!$G$5:$G$972,"<>*No disponible*") -> 5 | W9: =SUM(C9:V9) -> 90
B10: Mini PTZ | C10: =COUNTIFS('Base de Datos'!$C$5:$C$972,C$5,'Base de Datos'!$F$5:$F$972,$B10,'Base de Datos'!$G$5:$G$972,"<>*No disponible*") -> 5 | D10: =COUNTIFS('Base de Datos'!$C$5:$C$972,D$5,'Base de Datos'!$F$5:$F$972,$B10,'Base de Datos'!$G$5:$G$972,"<>*No disponible*") -> 5 | E10: =COUNTIFS('Base de Datos'!$C$5:$C$972,E$5,'Base de Datos'!$F$5:$F$972,$B10,'Base de Datos'!$G$5:$G$972,"<>*No disponible*") -> 5 | F10: =COUNTIFS('Base de Datos'!$C$5:$C$972,F$5,'Base de Datos'!$F$5:$F$972,$B10,'Base de Datos'!$G$5:$G$972,"<>*No disponible*") -> 0 | G10: =COUNTIFS('Base de Datos'!$C$5:$C$972,G$5,'Base de Datos'!$F$5:$F$972,$B10,'Base de Datos'!$G$5:$G$972,"<>*No disponible*") -> 5 | H10: =COUNTIFS('Base de Datos'!$C$5:$C$972,H$5,'Base de Datos'!$F$5:$F$972,$B10,'Base de Datos'!$G$5:$G$972,"<>*No disponible*") -> 0 | I10: =COUNTIFS('Base de Datos'!$C$5:$C$972,I$5,'Base de Datos'!$F$5:$F$972,$B10,'Base de Datos'!$G$5:$G$972,"<>*No disponible*") -> 0 | J10: =COUNTIFS('Base de Datos'!$C$5:$C$972,J$5,'Base de Datos'!$F$5:$F$972,$B10,'Base de Datos'!$G$5:$G$972,"<>*No disponible*") -> 5 | ... V10: =COUNTIFS('Base de Datos'!$C$5:$C$972,V$5,'Base de Datos'!$F$5:$F$972,$B10,'Base de Datos'!$G$5:$G$972,"<>*No disponible*") -> 0 | W10: =SUM(C10:V10) -> 40
B11: Turrón (Box) | C11: =COUNTIFS('Base de Datos'!$C$5:$C$972,C$5,'Base de Datos'!$F$5:$F$972,$B11,'Base de Datos'!$G$5:$G$972,"<>*No disponible*") -> 5 | D11: =COUNTIFS('Base de Datos'!$C$5:$C$972,D$5,'Base de Datos'!$F$5:$F$972,$B11,'Base de Datos'!$G$5:$G$972,"<>*No disponible*") -> 5 | E11: =COUNTIFS('Base de Datos'!$C$5:$C$972,E$5,'Base de Datos'!$F$5:$F$972,$B11,'Base de Datos'!$G$5:$G$972,"<>*No disponible*") -> 5 | F11: =COUNTIFS('Base de Datos'!$C$5:$C$972,F$5,'Base de Datos'!$F$5:$F$972,$B11,'Base de Datos'!$G$5:$G$972,"<>*No disponible*") -> 0 | G11: =COUNTIFS('Base de Datos'!$C$5:$C$972,G$5,'Base de Datos'!$F$5:$F$972,$B11,'Base de Datos'!$G$5:$G$972,"<>*No disponible*") -> 0 | H11: =COUNTIFS('Base de Datos'!$C$5:$C$972,H$5,'Base de Datos'!$F$5:$F$972,$B11,'Base de Datos'!$G$5:$G$972,"<>*No disponible*") -> 5 | I11: =COUNTIFS('Base de Datos'!$C$5:$C$972,I$5,'Base de Datos'!$F$5:$F$972,$B11,'Base de Datos'!$G$5:$G$972,"<>*No disponible*") -> 5 | J11: =COUNTIFS('Base de Datos'!$C$5:$C$972,J$5,'Base de Datos'!$F$5:$F$972,$B11,'Base de Datos'!$G$5:$G$972,"<>*No disponible*") -> 5 | ... V11: =COUNTIFS('Base de Datos'!$C$5:$C$972,V$5,'Base de Datos'!$F$5:$F$972,$B11,'Base de Datos'!$G$5:$G$972,"<>*No disponible*") -> 0 | W11: =SUM(C11:V11) -> 40
B12: Ojo de Pez (Fisheye) | C12: =COUNTIFS('Base de Datos'!$C$5:$C$972,C$5,'Base de Datos'!$F$5:$F$972,$B12,'Base de Datos'!$G$5:$G$972,"<>*No disponible*") -> 5 | D12: =COUNTIFS('Base de Datos'!$C$5:$C$972,D$5,'Base de Datos'!$F$5:$F$972,$B12,'Base de Datos'!$G$5:$G$972,"<>*No disponible*") -> 5 | E12: =COUNTIFS('Base de Datos'!$C$5:$C$972,E$5,'Base de Datos'!$F$5:$F$972,$B12,'Base de Datos'!$G$5:$G$972,"<>*No disponible*") -> 5 | F12: =COUNTIFS('Base de Datos'!$C$5:$C$972,F$5,'Base de Datos'!$F$5:$F$972,$B12,'Base de Datos'!$G$5:$G$972,"<>*No disponible*") -> 5 | G12: =COUNTIFS('Base de Datos'!$C$5:$C$972,G$5,'Base de Datos'!$F$5:$F$972,$B12,'Base de Datos'!$G$5:$G$972,"<>*No disponible*") -> 5 | H12: =COUNTIFS('Base de Datos'!$C$5:$C$972,H$5,'Base de Datos'!$F$5:$F$972,$B12,'Base de Datos'!$G$5:$G$972,"<>*No disponible*") -> 0 | I12: =COUNTIFS('Base de Datos'!$C$5:$C$972,I$5,'Base de Datos'!$F$5:$F$972,$B12,'Base de Datos'!$G$5:$G$972,"<>*No disponible*") -> 5 | J12: =COUNTIFS('Base de Datos'!$C$5:$C$972,J$5,'Base de Datos'!$F$5:$F$972,$B12,'Base de Datos'!$G$5:$G$972,"<>*No disponible*") -> 5 | ... V12: =COUNTIFS('Base de Datos'!$C$5:$C$972,V$5,'Base de Datos'!$F$5:$F$972,$B12,'Base de Datos'!$G$5:$G$972,"<>*No disponible*") -> 0 | W12: =SUM(C12:V12) -> 65
B13: Multisensor / Panorámica | C13: =COUNTIFS('Base de Datos'!$C$5:$C$972,C$5,'Base de Datos'!$F$5:$F$972,$B13,'Base de Datos'!$G$5:$G$972,"<>*No disponible*") -> 5 | D13: =COUNTIFS('Base de Datos'!$C$5:$C$972,D$5,'Base de Datos'!$F$5:$F$972,$B13,'Base de Datos'!$G$5:$G$972,"<>*No disponible*") -> 5 | E13: =COUNTIFS('Base de Datos'!$C$5:$C$972,E$5,'Base de Datos'!$F$5:$F$972,$B13,'Base de Datos'!$G$5:$G$972,"<>*No disponible*") -> 5 | F13: =COUNTIFS('Base de Datos'!$C$5:$C$972,F$5,'Base de Datos'!$F$5:$F$972,$B13,'Base de Datos'!$G$5:$G$972,"<>*No disponible*") -> 5 | G13: =COUNTIFS('Base de Datos'!$C$5:$C$972,G$5,'Base de Datos'!$F$5:$F$972,$B13,'Base de Datos'!$G$5:$G$972,"<>*No disponible*") -> 5 | H13: =COUNTIFS('Base de Datos'!$C$5:$C$972,H$5,'Base de Datos'!$F$5:$F$972,$B13,'Base de Datos'!$G$5:$G$972,"<>*No disponible*") -> 0 | I13: =COUNTIFS('Base de Datos'!$C$5:$C$972,I$5,'Base de Datos'!$F$5:$F$972,$B13,'Base de Datos'!$G$5:$G$972,"<>*No disponible*") -> 5 | J13: =COUNTIFS('Base de Datos'!$C$5:$C$972,J$5,'Base de Datos'!$F$5:$F$972,$B13,'Base de Datos'!$G$5:$G$972,"<>*No disponible*") -> 5 | ... V13: =COUNTIFS('Base de Datos'!$C$5:$C$972,V$5,'Base de Datos'!$F$5:$F$972,$B13,'Base de Datos'!$G$5:$G$972,"<>*No disponible*") -> 0 | W13: =SUM(C13:V13) -> 45
B14: Oculta (Pinhole) | C14: =COUNTIFS('Base de Datos'!$C$5:$C$972,C$5,'Base de Datos'!$F$5:$F$972,$B14,'Base de Datos'!$G$5:$G$972,"<>*No disponible*") -> 5 | D14: =COUNTIFS('Base de Datos'!$C$5:$C$972,D$5,'Base de Datos'!$F$5:$F$972,$B14,'Base de Datos'!$G$5:$G$972,"<>*No disponible*") -> 0 | E14: =COUNTIFS('Base de Datos'!$C$5:$C$972,E$5,'Base de Datos'!$F$5:$F$972,$B14,'Base de Datos'!$G$5:$G$972,"<>*No disponible*") -> 0 | F14: =COUNTIFS('Base de Datos'!$C$5:$C$972,F$5,'Base de Datos'!$F$5:$F$972,$B14,'Base de Datos'!$G$5:$G$972,"<>*No disponible*") -> 0 | G14: =COUNTIFS('Base de Datos'!$C$5:$C$972,G$5,'Base de Datos'!$F$5:$F$972,$B14,'Base de Datos'!$G$5:$G$972,"<>*No disponible*") -> 0 | H14: =COUNTIFS('Base de Datos'!$C$5:$C$972,H$5,'Base de Datos'!$F$5:$F$972,$B14,'Base de Datos'!$G$5:$G$972,"<>*No disponible*") -> 0 | I14: =COUNTIFS('Base de Datos'!$C$5:$C$972,I$5,'Base de Datos'!$F$5:$F$972,$B14,'Base de Datos'!$G$5:$G$972,"<>*No disponible*") -> 0 | J14: =COUNTIFS('Base de Datos'!$C$5:$C$972,J$5,'Base de Datos'!$F$5:$F$972,$B14,'Base de Datos'!$G$5:$G$972,"<>*No disponible*") -> 0 | ... V14: =COUNTIFS('Base de Datos'!$C$5:$C$972,V$5,'Base de Datos'!$F$5:$F$972,$B14,'Base de Datos'!$G$5:$G$972,"<>*No disponible*") -> 0 | W14: =SUM(C14:V14) -> 15
B15: Térmica | C15: =COUNTIFS('Base de Datos'!$C$5:$C$972,C$5,'Base de Datos'!$F$5:$F$972,$B15,'Base de Datos'!$G$5:$G$972,"<>*No disponible*") -> 5 | D15: =COUNTIFS('Base de Datos'!$C$5:$C$972,D$5,'Base de Datos'!$F$5:$F$972,$B15,'Base de Datos'!$G$5:$G$972,"<>*No disponible*") -> 5 | E15: =COUNTIFS('Base de Datos'!$C$5:$C$972,E$5,'Base de Datos'!$F$5:$F$972,$B15,'Base de Datos'!$G$5:$G$972,"<>*No disponible*") -> 5 | F15: =COUNTIFS('Base de Datos'!$C$5:$C$972,F$5,'Base de Datos'!$F$5:$F$972,$B15,'Base de Datos'!$G$5:$G$972,"<>*No disponible*") -> 5 | G15: =COUNTIFS('Base de Datos'!$C$5:$C$972,G$5,'Base de Datos'!$F$5:$F$972,$B15,'Base de Datos'!$G$5:$G$972,"<>*No disponible*") -> 5 | H15: =COUNTIFS('Base de Datos'!$C$5:$C$972,H$5,'Base de Datos'!$F$5:$F$972,$B15,'Base de Datos'!$G$5:$G$972,"<>*No disponible*") -> 0 | I15: =COUNTIFS('Base de Datos'!$C$5:$C$972,I$5,'Base de Datos'!$F$5:$F$972,$B15,'Base de Datos'!$G$5:$G$972,"<>*No disponible*") -> 5 | J15: =COUNTIFS('Base de Datos'!$C$5:$C$972,J$5,'Base de Datos'!$F$5:$F$972,$B15,'Base de Datos'!$G$5:$G$972,"<>*No disponible*") -> 5 | ... V15: =COUNTIFS('Base de Datos'!$C$5:$C$972,V$5,'Base de Datos'!$F$5:$F$972,$B15,'Base de Datos'!$G$5:$G$972,"<>*No disponible*") -> 0 | W15: =SUM(C15:V15) -> 45
B16: LPR (Matrículas) | C16: =COUNTIFS('Base de Datos'!$C$5:$C$972,C$5,'Base de Datos'!$F$5:$F$972,$B16,'Base de Datos'!$G$5:$G$972,"<>*No disponible*") -> 5 | D16: =COUNTIFS('Base de Datos'!$C$5:$C$972,D$5,'Base de Datos'!$F$5:$F$972,$B16,'Base de Datos'!$G$5:$G$972,"<>*No disponible*") -> 5 | E16: =COUNTIFS('Base de Datos'!$C$5:$C$972,E$5,'Base de Datos'!$F$5:$F$972,$B16,'Base de Datos'!$G$5:$G$972,"<>*No disponible*") -> 5 | F16: =COUNTIFS('Base de Datos'!$C$5:$C$972,F$5,'Base de Datos'!$F$5:$F$972,$B16,'Base de Datos'!$G$5:$G$972,"<>*No disponible*") -> 5 | G16: =COUNTIFS('Base de Datos'!$C$5:$C$972,G$5,'Base de Datos'!$F$5:$F$972,$B16,'Base de Datos'!$G$5:$G$972,"<>*No disponible*") -> 0 | H16: =COUNTIFS('Base de Datos'!$C$5:$C$972,H$5,'Base de Datos'!$F$5:$F$972,$B16,'Base de Datos'!$G$5:$G$972,"<>*No disponible*") -> 0 | I16: =COUNTIFS('Base de Datos'!$C$5:$C$972,I$5,'Base de Datos'!$F$5:$F$972,$B16,'Base de Datos'!$G$5:$G$972,"<>*No disponible*") -> 0 | J16: =COUNTIFS('Base de Datos'!$C$5:$C$972,J$5,'Base de Datos'!$F$5:$F$972,$B16,'Base de Datos'!$G$5:$G$972,"<>*No disponible*") -> 5 | ... V16: =COUNTIFS('Base de Datos'!$C$5:$C$972,V$5,'Base de Datos'!$F$5:$F$972,$B16,'Base de Datos'!$G$5:$G$972,"<>*No disponible*") -> 0 | W16: =SUM(C16:V16) -> 50
B17: Dual-Lente | C17: =COUNTIFS('Base de Datos'!$C$5:$C$972,C$5,'Base de Datos'!$F$5:$F$972,$B17,'Base de Datos'!$G$5:$G$972,"<>*No disponible*") -> 5 | D17: =COUNTIFS('Base de Datos'!$C$5:$C$972,D$5,'Base de Datos'!$F$5:$F$972,$B17,'Base de Datos'!$G$5:$G$972,"<>*No disponible*") -> 0 | E17: =COUNTIFS('Base de Datos'!$C$5:$C$972,E$5,'Base de Datos'!$F$5:$F$972,$B17,'Base de Datos'!$G$5:$G$972,"<>*No disponible*") -> 5 | F17: =COUNTIFS('Base de Datos'!$C$5:$C$972,F$5,'Base de Datos'!$F$5:$F$972,$B17,'Base de Datos'!$G$5:$G$972,"<>*No disponible*") -> 0 | G17: =COUNTIFS('Base de Datos'!$C$5:$C$972,G$5,'Base de Datos'!$F$5:$F$972,$B17,'Base de Datos'!$G$5:$G$972,"<>*No disponible*") -> 0 | H17: =COUNTIFS('Base de Datos'!$C$5:$C$972,H$5,'Base de Datos'!$F$5:$F$972,$B17,'Base de Datos'!$G$5:$G$972,"<>*No disponible*") -> 0 | I17: =COUNTIFS('Base de Datos'!$C$5:$C$972,I$5,'Base de Datos'!$F$5:$F$972,$B17,'Base de Datos'!$G$5:$G$972,"<>*No disponible*") -> 5 | J17: =COUNTIFS('Base de Datos'!$C$5:$C$972,J$5,'Base de Datos'!$F$5:$F$972,$B17,'Base de Datos'!$G$5:$G$972,"<>*No disponible*") -> 0 | ... V17: =COUNTIFS('Base de Datos'!$C$5:$C$972,V$5,'Base de Datos'!$F$5:$F$972,$B17,'Base de Datos'!$G$5:$G$972,"<>*No disponible*") -> 0 | W17: =SUM(C17:V17) -> 45
... B19: Interior WiFi | C19: =COUNTIFS('Base de Datos'!$C$5:$C$972,C$5,'Base de Datos'!$F$5:$F$972,$B19,'Base de Datos'!$G$5:$G$972,"<>*No disponible*") -> 0 | D19: =COUNTIFS('Base de Datos'!$C$5:$C$972,D$5,'Base de Datos'!$F$5:$F$972,$B19,'Base de Datos'!$G$5:$G$972,"<>*No disponible*") -> 5 | E19: =COUNTIFS('Base de Datos'!$C$5:$C$972,E$5,'Base de Datos'!$F$5:$F$972,$B19,'Base de Datos'!$G$5:$G$972,"<>*No disponible*") -> 5 | F19: =COUNTIFS('Base de Datos'!$C$5:$C$972,F$5,'Base de Datos'!$F$5:$F$972,$B19,'Base de Datos'!$G$5:$G$972,"<>*No disponible*") -> 0 | G19: =COUNTIFS('Base de Datos'!$C$5:$C$972,G$5,'Base de Datos'!$F$5:$F$972,$B19,'Base de Datos'!$G$5:$G$972,"<>*No disponible*") -> 0 | H19: =COUNTIFS('Base de Datos'!$C$5:$C$972,H$5,'Base de Datos'!$F$5:$F$972,$B19,'Base de Datos'!$G$5:$G$972,"<>*No disponible*") -> 5 | I19: =COUNTIFS('Base de Datos'!$C$5:$C$972,I$5,'Base de Datos'!$F$5:$F$972,$B19,'Base de Datos'!$G$5:$G$972,"<>*No disponible*") -> 0 | J19: =COUNTIFS('Base de Datos'!$C$5:$C$972,J$5,'Base de Datos'!$F$5:$F$972,$B19,'Base de Datos'!$G$5:$G$972,"<>*No disponible*") -> 0 | ... V19: =COUNTIFS('Base de Datos'!$C$5:$C$972,V$5,'Base de Datos'!$F$5:$F$972,$B19,'Base de Datos'!$G$5:$G$972,"<>*No disponible*") -> 5 | W19: =SUM(C19:V19) -> 45
B20: Modelos activos por marca | C20: =SUM(C6:C19) -> 65 | D20: =SUM(D6:D19) -> 60 | E20: =SUM(E6:E19) -> 65 | F20: =SUM(F6:F19) -> 45 | G20: =SUM(G6:G19) -> 45 | H20: =SUM(H6:H19) -> 35 | I20: =SUM(I6:I19) -> 50 | J20: =SUM(J6:J19) -> 55 | ... W20: =SUM(W6:W19) -> 860
B23: Estadísticas por marca
B24: Marca | C24: Nivel | D24: País | E24: Modelos activos | F24: Precio mín. (USD) | G24: Precio máx. (USD) | H24: Precio promedio (USD)
B25: Axis Communications | C25: Premium | D25: Suecia | E25: =COUNTIFS('Base de Datos'!$C$5:$C$972,$B25,'Base de Datos'!$G$5:$G$972,"<>*No disponible*") -> 65 | F25: =MIN('Base de Datos'!$AB$5:$AB$70) -> 260 | G25: =MAX('Base de Datos'!$AB$5:$AB$70) -> 17380 | H25: =IFERROR(ROUND(AVERAGE('Base de Datos'!$AB$5:$AB$70),0),"—") -> 2819
B26: Bosch Security Systems | C26: Premium | D26: Alemania | E26: =COUNTIFS('Base de Datos'!$C$5:$C$972,$B26,'Base de Datos'!$G$5:$G$972,"<>*No disponible*") -> 60 | F26: =MIN('Base de Datos'!$AB$71:$AB$132) -> 100 | G26: =MAX('Base de Datos'!$AB$71:$AB$132) -> 25300 | H26: =IFERROR(ROUND(AVERAGE('Base de Datos'!$AB$71:$AB$132),0),"—") -> 2731
B27: Hanwha Vision (Wisenet) | C27: Premium | D27: Corea del Sur | E27: =COUNTIFS('Base de Datos'!$C$5:$C$972,$B27,'Base de Datos'!$G$5:$G$972,"<>*No disponible*") -> 65 | F27: =MIN('Base de Datos'!$AB$133:$AB$198) -> 45 | G27: =MAX('Base de Datos'!$AB$133:$AB$198) -> 10780 | H27: =IFERROR(ROUND(AVERAGE('Base de Datos'!$AB$133:$AB$198),0),"—") -> 1635
B28: Avigilon (Motorola) | C28: Premium | D28: Canadá | E28: =COUNTIFS('Base de Datos'!$C$5:$C$972,$B28,'Base de Datos'!$G$5:$G$972,"<>*No disponible*") -> 45 | F28: =MIN('Base de Datos'!$AB$199:$AB$248) -> 360 | G28: =MAX('Base de Datos'!$AB$199:$AB$248) -> 14300 | H28: =IFERROR(ROUND(AVERAGE('Base de Datos'!$AB$199:$AB$248),0),"—") -> 2528
B29: Pelco (Motorola) | C29: Premium | D29: EE. UU. | E29: =COUNTIFS('Base de Datos'!$C$5:$C$972,$B29,'Base de Datos'!$G$5:$G$972,"<>*No disponible*") -> 45 | F29: =MIN('Base de Datos'!$AB$249:$AB$298) -> 270 | G29: =MAX('Base de Datos'!$AB$249:$AB$298) -> 12760 | H29: =IFERROR(ROUND(AVERAGE('Base de Datos'!$AB$249:$AB$298),0),"—") -> 2571
B30: Honeywell Security | C30: Premium | D30: EE. UU. | E30: =COUNTIFS('Base de Datos'!$C$5:$C$972,$B30,'Base de Datos'!$G$5:$G$972,"<>*No disponible*") -> 35 | F30: =MIN('Base de Datos'!$AB$299:$AB$340) -> 65 | G30: =MAX('Base de Datos'!$AB$299:$AB$340) -> 3080 | H30: =IFERROR(ROUND(AVERAGE('Base de Datos'!$AB$299:$AB$340),0),"—") -> 510
B31: MOBOTIX | C31: Premium | D31: Alemania | E31: =COUNTIFS('Base de Datos'!$C$5:$C$972,$B31,'Base de Datos'!$G$5:$G$972,"<>*No disponible*") -> 50 | F31: =MIN('Base de Datos'!$AB$341:$AB$394) -> 445 | G31: =MAX('Base de Datos'!$AB$341:$AB$394) -> 15180 | H31: =IFERROR(ROUND(AVERAGE('Base de Datos'!$AB$341:$AB$394),0),"—") -> 2185
B32: Vivotek | C32: Medio-Alto | D32: Taiwán | E32: =COUNTIFS('Base de Datos'!$C$5:$C$972,$B32,'Base de Datos'!$G$5:$G$972,"<>*No disponible*") -> 55 | F32: =MIN('Base de Datos'!$AB$395:$AB$452) -> 150 | G32: =MAX('Base de Datos'!$AB$395:$AB$452) -> 10560 | H32: =IFERROR(ROUND(AVERAGE('Base de Datos'!$AB$395:$AB$452),0),"—") -> 1308
B33: IDIS | C33: Medio-Alto | D33: Corea del Sur | E33: =COUNTIFS('Base de Datos'!$C$5:$C$972,$B33,'Base de Datos'!$G$5:$G$972,"<>*No disponible*") -> 35 | F33: =MIN('Base de Datos'!$AB$453:$AB$494) -> 125 | G33: =MAX('Base de Datos'!$AB$453:$AB$494) -> 2530 | H33: =IFERROR(ROUND(AVERAGE('Base de Datos'!$AB$453:$AB$494),0),"—") -> 510
B34: Verkada | C34: Premium (Cloud) | D34: EE. UU. | E34: =COUNTIFS('Base de Datos'!$C$5:$C$972,$B34,'Base de Datos'!$G$5:$G$972,"<>*No disponible*") -> 30 | F34: =MIN('Base de Datos'!$AB$495:$AB$532) -> 300 | G34: =MAX('Base de Datos'!$AB$495:$AB$532) -> 1870 | H34: =IFERROR(ROUND(AVERAGE('Base de Datos'!$AB$495:$AB$532),0),"—") -> 853
B35: Ubiquiti (UniFi Protect) | C35: Medio | D35: EE. UU. | E35: =COUNTIFS('Base de Datos'!$C$5:$C$972,$B35,'Base de Datos'!$G$5:$G$972,"<>*No disponible*") -> 30 | F35: =MIN('Base de Datos'!$AB$533:$AB$570) -> 100 | G35: =MAX('Base de Datos'!$AB$533:$AB$570) -> 1540 | H35: =IFERROR(ROUND(AVERAGE('Base de Datos'!$AB$533:$AB$570),0),"—") -> 387
B36: Hikvision | C36: Medio | D36: China | E36: =COUNTIFS('Base de Datos'!$C$5:$C$972,$B36,'Base de Datos'!$G$5:$G$972,"<>*No disponible*") -> 70 | F36: =MIN('Base de Datos'!$AB$571:$AB$640) -> 40 | G36: =MAX('Base de Datos'!$AB$571:$AB$640) -> 4180 | H36: =IFERROR(ROUND(AVERAGE('Base de Datos'!$AB$571:$AB$640),0),"—") -> 571
B37: Dahua Technology | C37: Medio | D37: China | E37: =COUNTIFS('Base de Datos'!$C$5:$C$972,$B37,'Base de Datos'!$G$5:$G$972,"<>*No disponible*") -> 70 | F37: =MIN('Base de Datos'!$AB$641:$AB$710) -> 25 | G37: =MAX('Base de Datos'!$AB$641:$AB$710) -> 2090 | H37: =IFERROR(ROUND(AVERAGE('Base de Datos'!$AB$641:$AB$710),0),"—") -> 323
B38: Uniview (UNV) | C38: Medio | D38: China | E38: =COUNTIFS('Base de Datos'!$C$5:$C$972,$B38,'Base de Datos'!$G$5:$G$972,"<>*No disponible*") -> 45 | F38: =MIN('Base de Datos'!$AB$711:$AB$760) -> 50 | G38: =MAX('Base de Datos'!$AB$711:$AB$760) -> 1520 | H38: =IFERROR(ROUND(AVERAGE('Base de Datos'!$AB$711:$AB$760),0),"—") -> 314
B39: HiLook (Hikvision) | C39: Económico | D39: China | E39: =COUNTIFS('Base de Datos'!$C$5:$C$972,$B39,'Base de Datos'!$G$5:$G$972,"<>*No disponible*") -> 20 | F39: =MIN('Base de Datos'!$AB$761:$AB$790) -> 25 | G39: =MAX('Base de Datos'!$AB$761:$AB$790) -> 170 | H39: =IFERROR(ROUND(AVERAGE('Base de Datos'!$AB$761:$AB$790),0),"—") -> 68
B40: Imou (Dahua) | C40: Económico | D40: China | E40: =COUNTIFS('Base de Datos'!$C$5:$C$972,$B40,'Base de Datos'!$G$5:$G$972,"<>*No disponible*") -> 30 | F40: =MIN('Base de Datos'!$AB$791:$AB$828) -> 25 | G40: =MAX('Base de Datos'!$AB$791:$AB$828) -> 170 | H40: =IFERROR(ROUND(AVERAGE('Base de Datos'!$AB$791:$AB$828),0),"—") -> 58
B41: EZVIZ (Hikvision) | C41: Económico | D41: China | E41: =COUNTIFS('Base de Datos'!$C$5:$C$972,$B41,'Base de Datos'!$G$5:$G$972,"<>*No disponible*") -> 30 | F41: =MIN('Base de Datos'!$AB$829:$AB$866) -> 25 | G41: =MAX('Base de Datos'!$AB$829:$AB$866) -> 195 | H41: =IFERROR(ROUND(AVERAGE('Base de Datos'!$AB$829:$AB$866),0),"—") -> 62
B42: Reolink | C42: Económico | D42: China | E42: =COUNTIFS('Base de Datos'!$C$5:$C$972,$B42,'Base de Datos'!$G$5:$G$972,"<>*No disponible*") -> 30 | F42: =MIN('Base de Datos'!$AB$867:$AB$904) -> 25 | G42: =MAX('Base de Datos'!$AB$867:$AB$904) -> 420 | H42: =IFERROR(ROUND(AVERAGE('Base de Datos'!$AB$867:$AB$904),0),"—") -> 127
B43: TP-Link VIGI | C43: Económico | D43: China | E43: =COUNTIFS('Base de Datos'!$C$5:$C$972,$B43,'Base de Datos'!$G$5:$G$972,"<>*No disponible*") -> 25 | F43: =MIN('Base de Datos'!$AB$905:$AB$938) -> 25 | G43: =MAX('Base de Datos'!$AB$905:$AB$938) -> 395 | H43: =IFERROR(ROUND(AVERAGE('Base de Datos'!$AB$905:$AB$938),0),"—") -> 104
B44: Tenda Security | C44: Económico | D44: China | E44: =COUNTIFS('Base de Datos'!$C$5:$C$972,$B44,'Base de Datos'!$G$5:$G$972,"<>*No disponible*") -> 25 | F44: =MIN('Base de Datos'!$AB$939:$AB$972) -> 25 | G44: =MAX('Base de Datos'!$AB$939:$AB$972) -> 120 | H44: =IFERROR(ROUND(AVERAGE('Base de Datos'!$AB$939:$AB$972),0),"—") -> 50
B45: TOTAL / GENERAL | E45: =SUM(E25:E44) -> 860 | F45: =MIN(F25:F44) -> 25 | G45: =MAX(G25:G44) -> 25300 | H45: =IFERROR(ROUND(AVERAGE('Base de Datos'!$AB$5:$AB$972),0),"—") -> 1193
B48: Estadísticas de equipamiento por categoría
...

Sheet Base de Datos
B2: Base de Datos Técnica — Cámaras CCTV (20 marcas × 14 tipos × 5 variantes)
B4: N° | C4: Marca | D4: Nivel | E4: País | F4: Tipo de Cámara | G4: Modelo | H4: Resolución (MP) | I4: Resolución Máx. | J4: Sensor | K4: Lente | L4: Visión Nocturna | M4: WDR | N4: Analíticas IA | O4: Compresión | P4: ONVIF | Q4: Audio | R4: E/S Alarma | S4: Almac. Local | T4: Protección | U4: PoE | V4: Consumo | W4: Temp. Operación | X4: Dimensiones | Y4: Peso | Z4: Certificaciones | AA4: Uso Recomendado | AB4: Precio Ref. (USD) | AC4: Proveedor | AD4: Stock | AE4: Observaciones
B5: 1 | C5: Axis Communications | D5: Premium | E5: Suecia | F5: Domo | G5: AXIS M3086-V | H5: 2 MP | I5: 1920 × 1080 | J5: 1/2.8" Sony Starvis | K5: 3–9 mm varifocal P-Iris | L5: OptimizedIR 40 m | M5: Forensic WDR | N5: AXIS Object Analytics | O5: H.265 (Zipstream) / H.264 | P5: Perfil S, T, G | Q5: E/S (según modelo) | R5: E/S (según modelo) | S5: microSD 256 GB (AXIS Surveillance) | T5: IP66 / IK10 | U5: 802.3af | V5: 12.9 W máx | W5: -30 °C a +50 °C | X5: Ø 160 × 120 mm | Y5: 1.0 kg | Z5: CE, FCC, EN 50121 | AA5: Interior/Exterior | AB5: 545 | AE5: Variante económica de la gama
B6: 2 | C6: Axis Communications | D6: Premium | E6: Suecia | F6: Domo | G6: AXIS M3206-LVE | H6: 4 MP | I6: 2560 × 1440 | J6: 1/2.8" Sony Starvis | K6: 3–9 mm varifocal P-Iris | L6: OptimizedIR 40 m | M6: Forensic WDR | N6: AXIS Object Analytics | O6: H.265 (Zipstream) / H.264 | P6: Perfil S, T, G | Q6: E/S (según modelo) | R6: E/S (según modelo) | S6: microSD 256 GB (AXIS Surveillance) | T6: IP66 / IK10 | U6: 802.3af | V6: 12.9 W máx | W6: -30 °C a +50 °C | X6: Ø 160 × 120 mm | Y6: 1.0 kg | Z6: CE, FCC, EN 50121 | AA6: Interior/Exterior | AB6: 820 | AE6: Gama de entrada
B7: 3 | C7: Axis Communications | D7: Premium | E7: Suecia | F7: Domo | G7: AXIS P3245-LVE | H7: 4 MP | I7: 2560 × 1440 | J7: 1/2.8" Sony Starvis | K7: 3–9 mm varifocal P-Iris | L7: OptimizedIR 40 m | M7: Forensic WDR | N7: AXIS Object Analytics | O7: H.265 (Zipstream) / H.264 | P7: Perfil S, T, G | Q7: E/S (según modelo) | R7: E/S (según modelo) | S7: microSD 256 GB (AXIS Surveillance) | T7: IP66 / IK10 | U7: 802.3af | V7: 12.9 W máx | W7: -30 °C a +50 °C | X7: Ø 160 × 120 mm | Y7: 1.0 kg | Z7: CE, FCC, EN 50121 | AA7: Interior/Exterior | AB7: 1090 | AE7: Starlight para baja luz
B8: 4 | C8: Axis Communications | D8: Premium | E8: Suecia | F8: Domo | G8: AXIS P3265-LVE | H8: 8 MP (4K) | I8: 3840 × 2160 | J8: 1/2.8" Sony Starvis | K8: 3–9 mm varifocal P-Iris | L8: OptimizedIR 40 m | M8: Forensic WDR | N8: AXIS Object Analytics | O8: H.265 (Zipstream) / H.264 | P8: Perfil S, T, G | Q8: E/S (según modelo) | R8: E/S (según modelo) | S8: microSD 256 GB (AXIS Surveillance) | T8: IP66 / IK10 | U8: 802.3af | V8: 12.9 W máx | W8: -30 °C a +50 °C | X8: Ø 160 × 120 mm | Y8: 1.0 kg | Z8: CE, FCC, EN 50121 | AA8: Interior/Exterior | AB8: 1635 | AE8: Resolución y rendimiento mejorados
B9: 5 | C9: Axis Communications | D9: Premium | E9: Suecia | F9: Domo | G9: AXIS P3268-LVE | H9: 8 MP (4K) | I9: 3840 × 2160 | J9: 1/2.8" Sony Starvis | K9: 3–9 mm varifocal P-Iris | L9: OptimizedIR 40 m | M9: Forensic WDR | N9: AXIS Object Analytics | O9: H.265 (Zipstream) / H.264 | P9: Perfil S, T, G | Q9: E/S (según modelo) | R9: E/S (según modelo) | S9: microSD 256 GB (AXIS Surveillance) | T9: IP66 / IK10 | U9: 802.3af | V9: 12.9 W máx | W9: -30 °C a +50 °C | X9: Ø 160 × 120 mm | Y9: 1.0 kg | Z9: CE, FCC, EN 50121 | AA9: Interior/Exterior | AB9: 2400 | AE9: Tope de gama — máxima especificación
B10: 6 | C10: Axis Communications | D10: Premium | E10: Suecia | F10: Domo Antivandálica | G10: AXIS M3206-LVE | H10: 2 MP | I10: 1920 × 1080 | J10: 1/2.8" Sony Starvis | K10: 3–9 mm varifocal | L10: IR 20 m | M10: WDR | N10: Zipstream + analíticas básicas | O10: H.265 (Zipstream) / H.264 | P10: Perfil S, T, G | Q10: E/S (según modelo) | R10: E/S (según modelo) | S10: microSD 256 GB (AXIS Surveillance) | T10: IP66 / IK10 | U10: 802.3af | V10: 7.5 W máx | W10: -30 °C a +50 °C | X10: Ø 149 × 110 mm | Y10: 850 g | Z10: CE, FCC, EN 50121 | AA10: Interior/Exterior | AB10: 345 | AE10: Variante económica de la gama
B11: 7 | C11: Axis Communications | D11: Premium | E11: Suecia | F11: Domo Antivandálica | G11: AXIS P3245-LVE | H11: 4 MP | I11: 2560 × 1440 | J11: 1/2.8" Sony Starvis | K11: 3–9 mm varifocal | L11: IR 20 m | M11: WDR | N11: Zipstream + analíticas básicas | O11: H.265 (Zipstream) / H.264 | P11: Perfil S, T, G | Q11: E/S (según modelo) | R11: E/S (según modelo) | S11: microSD 256 GB (AXIS Surveillance) | T11: IP66 / IK10 | U11: 802.3af | V11: 7.5 W máx | W11: -30 °C a +50 °C | X11: Ø 149 × 110 mm | Y11: 850 g | Z11: CE, FCC, EN 50121 | AA11: Interior/Exterior | AB11: 520 | AE11: Gama de entrada
B12: 8 | C12: Axis Communications | D12: Premium | E12: Suecia | F12: Domo Antivandálica | G12: AXIS P3265-LVE | H12: 4 MP | I12: 2560 × 1440 | J12: 1/2.8" Sony Starvis | K12: 3–9 mm varifocal | L12: IR 20 m | M12: WDR | N12: Zipstream + analíticas básicas | O12: H.265 (Zipstream) / H.264 | P12: Perfil S, T, G | Q12: E/S (según modelo) | R12: E/S (según modelo) | S12: microSD 256 GB (AXIS Surveillance) | T12: IP66 / IK10 | U12: 802.3af | V12: 7.5 W máx | W12: -30 °C a +50 °C | X12: Ø 149 × 110 mm | Y12: 850 g | Z12: CE, FCC, EN 50121 | AA12: Interior/Exterior | AB12: 690 | AE12: Montaje antivandálico
B13: 9 | C13: Axis Communications | D13: Premium | E13: Suecia | F13: Domo Antivandálica | G13: AXIS Q3511-LVE | H13: 8 MP (4K) | I13: 3840 × 2160 | J13: 1/2.8" Sony Starvis | K13: 3–9 mm varifocal | L13: IR 20 m | M13: WDR | N13: Zipstream + analíticas básicas | O13: H.265 (Zipstream) / H.264 | P13: Perfil S, T, G | Q13: E/S (según modelo) | R13: E/S (según modelo) | S13: microSD 256 GB (AXIS Surveillance) | T13: IP66 / IK10 | U13: 802.3af | V13: 7.5 W máx | W13: -30 °C a +50 °C | X13: Ø 149 × 110 mm | Y13: 850 g | Z13: CE, FCC, EN 50121 | AA13: Interior/Exterior | AB13: 1035 | AE13: Resolución y rendimiento mejorados
B14: 10 | C14: Axis Communications | D14: Premium | E14: Suecia | F14: Domo Antivandálica | G14: AXIS Q3536-SLVE | H14: 8 MP (4K) | I14: 3840 × 2160 | J14: 1/2.8" Sony Starvis | K14: 3–9 mm varifocal | L14: IR 20 m | M14: WDR | N14: Zipstream + analíticas básicas | O14: H.265 (Zipstream) / H.264 | P14: Perfil S, T, G | Q14: E/S (según modelo) | R14: E/S (según modelo) | S14: microSD 256 GB (AXIS Surveillance) | T14: IP66 / IK10 | U14: 802.3af | V14: 7.5 W máx | W14: -30 °C a +50 °C | X14: Ø 149 × 110 mm | Y14: 850 g | Z14: CE, FCC, EN 50121 | AA14: Interior/Exterior | AB14: 1520 | AE14: Tope de gama — máxima especificación
B15: 11 | C15: Axis Communications | D15: Premium | E15: Suecia | F15: Bala | G15: AXIS M1135 | H15: 2 MP | I15: 1920 × 1080 | J15: 1/2.8" Sony Starvis | K15: 3–9 mm varifocal | L15: OptimizedIR 50 m | M15: Forensic WDR | N15: AXIS Object Analytics | O15: H.265 (Zipstream) / H.264 | P15: Perfil S, T, G | Q15: E/S (según modelo) | R15: E/S (según modelo) | S15: microSD 256 GB (AXIS Surveillance) | T15: IP66 / IK09 | U15: 802.3af | V15: 11.5 W máx | W15: -30 °C a +50 °C | X15: 265 × 96 × 86 mm | Y15: 950 g | Z15: CE, FCC, EN 50121 | AA15: Exterior | AB15: 470 | AE15: Variante económica de la gama
B16: 12 | C16: Axis Communications | D16: Premium | E16: Suecia | F16: Bala | G16: AXIS P1465-LE | H16: 4 MP | I16: 2560 × 1440 | J16: 1/2.8" Sony Starvis | K16: 3–9 mm varifocal | L16: OptimizedIR 50 m | M16: Forensic WDR | N16: AXIS Object Analytics | O16: H.265 (Zipstream) / H.264 | P16: Perfil S, T, G | Q16: E/S (según modelo) | R16: E/S (según modelo) | S16: microSD 256 GB (AXIS Surveillance) | T16: IP66 / IK09 | U16: 802.3af | V16: 11.5 W máx | W16: -30 °C a +50 °C | X16: 265 × 96 × 86 mm | Y16: 950 g | Z16: CE, FCC, EN 50121 | AA16: Exterior | AB16: 705 | AE16: Gama de entrada
... B69: 65 | C69: Axis Communications | D69: Premium | E69: Suecia | F69: IA Integrada | G69: AXIS Q1798-LE | H69: 8 MP (4K) | I69: 3840 × 2160 | J69: 1/2.8" Sony Starvis | K69: 3–9 mm varifocal | L69: OptimizedIR 50 m | M69: Forensic WDR | N69: ARTPEC-8 — Object Analytics (personas/vehículos) | O69: H.265 (Zipstream) / H.264 | P69: Perfil S, T, G | Q69: E/S (según modelo) | R69: E/S (según modelo) | S69: microSD 256 GB (AXIS Surveillance) | T69: IP66 / IK09 | U69: 802.3at | V69: 25 W máx | W69: -30 °C a +50 °C | X69: 336 × 138 × 106 mm | Y69: 2.4 kg | Z69: CE, FCC, EN 50121 | AA69: Exterior | AB69: 3035 | AE69: Tope de gama — máxima especificación
B70: 66 | C70: Axis Communications | D70: Premium | E70: Suecia | F70: Interior WiFi | G70: No disponible en portafolio | AE70: AXIS no comercializa cámaras WiFi de interior; referencia PoE: AXIS M1065-L (1080p)
B71: 67 | C71: Bosch Security Systems | D71: Premium | E71: Alemania | F71: Domo | G71: FLEXIDOME IP indoor 3000i (NDI-3502-AL) | H71: 2 MP | I71: 1920 × 1080 | J71: 1/2.8" CMOS | K71: 2.8–10 mm varifocal | L71: Día/Noche — IR 20 m | M71: WDR 120 dB | N71: Analíticas Bosch (movimiento inteligente) | O71: H.265 / H.264 (Smart Encoding) | P71: Perfil S, T, G | Q71: E/S integrada | R71: 1 E / 1 S | S71: microSD 512 GB | T71: IK10 (interior) | U71: 802.3af | V71: 7 W máx | W71: -30 °C a +55 °C | X71: Ø 140 × 95 mm | Y71: 700 g | Z71: CE, FCC, UL | AA71: Interior | AB71: 390 | AE71: Variante económica de la gama
B72: 68 | C72: Bosch Security Systems | D72: Premium | E72: Alemania | F72: Domo | G72: FLEXIDOME IP indoor 3000i (NDI-3503-AL) | H72: 4 MP | I72: 2560 × 1440 | J72: 1/2.8" CMOS | K72: 2.8–10 mm varifocal | L72: Día/Noche — IR 20 m | M72: WDR 120 dB | N72: Analíticas Bosch (movimiento inteligente) | O72: H.265 / H.264 (Smart Encoding) | P72: Perfil S, T, G | Q72: E/S integrada | R72: 1 E / 1 S | S72: microSD 512 GB | T72: IK10 (interior) | U72: 802.3af | V72: 7 W máx | W72: -30 °C a +55 °C | X72: Ø 140 × 95 mm | Y72: 700 g | Z72: CE, FCC, UL | AA72: Interior | AB72: 585 | AE72: Gama de entrada
B73: 69 | C73: Bosch Security Systems | D73: Premium | E73: Alemania | F73: Domo | G73: FLEXIDOME IP indoor 5000i (NDI-5502-AL) | H73: 4 MP | I73: 2560 × 1440 | J73: 1/2.8" CMOS | K73: 2.8–10 mm varifocal | L73: Día/Noche — IR 20 m | M73: WDR 120 dB | N73: Analíticas Bosch (movimiento inteligente) | O73: H.265 / H.264 (Smart Encoding) | P73: Perfil S, T, G | Q73: E/S integrada | R73: 1 E / 1 S | S73: microSD 512 GB | T73: IK10 (interior) | U73: 802.3af | V73: 7 W máx | W73: -30 °C a +55 °C | X73: Ø 140 × 95 mm | Y73: 700 g | Z73: CE, FCC, UL | AA73: Interior | AB73: 780 | AE73: Línea 5000i con IVA básico
B74: 70 | C74: Bosch Security Systems | D74: Premium | E74: Alemania | F74: Domo | G74: FLEXIDOME IP indoor 5000i (NDI-5503-AL) | H74: 8 MP (4K) | I74: 3840 × 2160 | J74: 1/2.8" CMOS | K74: 2.8–10 mm varifocal | L74: Día/Noche — IR 20 m | M74: WDR 120 dB | N74: Analíticas Bosch (movimiento inteligente) | O74: H.265 / H.264 (Smart Encoding) | P74: Perfil S, T, G | Q74: E/S integrada | R74: 1 E / 1 S | S74: microSD 512 GB | T74: IK10 (interior) | U74: 802.3af | V74: 7 W máx | W74: -30 °C a +55 °C | X74: Ø 140 × 95 mm | Y74: 700 g | Z74: CE, FCC, UL | AA74: Interior | AB74: 1170 | AE74: Resolución y rendimiento mejorados
B75: 71 | C75: Bosch Security Systems | D75: Premium | E75: Alemania | F75: Domo | G75: FLEXIDOME IP indoor 7000i (NDI-7503-Z12) | H75: 8 MP (4K) | I75: 3840 × 2160 | J75: 1/2.8" CMOS | K75: 2.8–10 mm varifocal | L75: Día/Noche — IR 20 m | M75: WDR 120 dB | N75: Analíticas Bosch (movimiento inteligente) | O75: H.265 / H.264 (Smart Encoding) | P75: Perfil S, T, G | Q75: E/S integrada | R75: 1 E / 1 S | S75: microSD 512 GB | T75: IK10 (interior) | U75: 802.3af | V75: 7 W máx | W75: -30 °C a +55 °C | X75: Ø 140 × 95 mm | Y75: 700 g | Z75: CE, FCC, UL | AA75: Interior | AB75: 1715 | AE75: Tope de gama — máxima especificación
B76: 72 | C76: Bosch Security Systems | D76: Premium | E76: Alemania | F76: Domo Antivandálica | G76: FLEXIDOME IP outdoor 3000i (NDE-3502-AL) | H76: 2 MP | I76: 1920 × 1080 | J76: 1/2.8" CMOS | K76: 2.8–10 mm varifocal | L76: IR 30 m | M76: WDR 120 dB | N76: Analíticas Bosch (movimiento inteligente) | O76: H.265 / H.264 (Smart Encoding) | P76: Perfil S, T, G | Q76: E/S integrada | R76: 1 E / 1 S | S76: microSD 512 GB | T76: IP66 / IK10 | U76: 802.3af | V76: 9 W máx | W76: -30 °C a +55 °C | X76: Ø 140 × 100 mm | Y76: 780 g | Z76: CE, FCC, UL | AA76: Exterior | AB76: 445 | AE76: Variante económica de la gama
B77: 73 | C77: Bosch Security Systems | D77: Premium | E77: Alemania | F77: Domo Antivandálica | G77: FLEXIDOME IP outdoor 3000i (NDE-3503-AL) | H77: 4 MP | I77: 2560 × 1440 | J77: 1/2.8" CMOS | K77: 2.8–10 mm varifocal | L77: IR 30 m | M77: WDR 120 dB | N77: Analíticas Bosch (movimiento inteligente) | O77: H.265 / H.264 (Smart Encoding) | P77: Perfil S, T, G | Q77: E/S integrada | R77: 1 E / 1 S | S77: microSD 512 GB | T77: IP66 / IK10 | U77: 802.3af | V77: 9 W máx | W77: -30 °C a +55 °C | X77: Ø 140 × 100 mm | Y77: 780 g | Z77: CE, FCC, UL | AA77: Exterior | AB77: 670 | AE77: Gama de entrada
B78: 74 | C78: Bosch Security Systems | D78: Premium | E78: Alemania | F78: Domo Antivandálica | G78: FLEXIDOME IP outdoor 5000i (NDE-5502-AL) | H78: 4 MP | I78: 2560 × 1440 | J78: 1/2.8" CMOS | K78: 2.8–10 mm varifocal | L78: IR 30 m | M78: WDR 120 dB | N78: Analíticas Bosch (movimiento inteligente) | O78: H.265 / H.264 (Smart Encoding) | P78: Perfil S, T, G | Q78: E/S integrada | R78: 1 E / 1 S | S78: microSD 512 GB | T78: IP66 / IK10 | U78: 802.3af | V78: 9 W máx | W78: -30 °C a +55 °C | X78: Ø 140 × 100 mm | Y78: 780 g | Z78: CE, FCC, UL | AA78: Exterior | AB78: 890 | AE78: Antivandálica IK10
B79: 75 | C79: Bosch Security Systems | D79: Premium | E79: Alemania | F79: Domo Antivandálica | G79: FLEXIDOME IP outdoor 5000i (NDE-5503-AL) | H79: 8 MP (4K) | I79: 3840 × 2160 | J79: 1/2.8" CMOS | K79: 2.8–10 mm varifocal | L79: IR 30 m | M79: WDR 120 dB | N79: Analíticas Bosch (movimiento inteligente) | O79: H.265 / H.264 (Smart Encoding) | P79: Perfil S, T, G | Q79: E/S integrada | R79: 1 E / 1 S | S79: microSD 512 GB | T79: IP66 / IK10 | U79: 802.3af | V79: 9 W máx | W79: -30 °C a +55 °C | X79: Ø 140 × 100 mm | Y79: 780 g | Z79: CE, FCC, UL | AA79: Exterior | AB79: 1335 | AE79: Resolución y rendimiento mejorados
B80: 76 | C80: Bosch Security Systems | D80: Premium | E80: Alemania | F80: Domo Antivandálica | G80: FLEXIDOME IP outdoor 7000i (NDE-7503-Z12) | H80: 8 MP (4K) | I80: 3840 × 2160 | J80: 1/2.8" CMOS | K80: 2.8–10 mm varifocal | L80: IR 30 m | M80: WDR 120 dB | N80: Analíticas Bosch (movimiento inteligente) | O80: H.265 / H.264 (Smart Encoding) | P80: Perfil S, T, G | Q80: E/S integrada | R80: 1 E / 1 S | S80: microSD 512 GB | T80: IP66 / IK10 | U80: 802.3af | V80: 9 W máx | W80: -30 °C a +55 °C | X80: Ø 140 × 100 mm | Y80: 780 g | Z80: CE, FCC, UL | AA80: Exterior | AB80: 1960 | AE80: Tope de gama — máxima especificación
B81: 77 | C81: Bosch Security Systems | D81: Premium | E81: Alemania | F81: Bala | G81: DINION IP 3000i IR (NBE-3502-AL) | H81: 2 MP | I81: 1920 × 1080 | J81: 1/2.8" CMOS | K81: 3–10 mm varifocal | L81: IR 40 m | M81: WDR 120 dB | N81: Analíticas Bosch | O81: H.265 / H.264 (Smart Encoding) | P81: Perfil S, T, G | Q81: E/S integrada | R81: 1 E / 1 S | S81: microSD 512 GB | T81: IP66 | U81: 802.3af | V81: 9 W máx | W81: -30 °C a +55 °C | X81: 240 × 90 × 90 mm | Y81: 1.1 kg | Z81: CE, FCC, UL | AA81: Exterior | AB81: 465 | AE81: Variante económica de la gama
B82: 78 | C82: Bosch Security Systems | D82: Premium | E82: Alemania | F82: Bala | G82: DINION IP 3000i IR (NBE-3503-AL) | H82: 4 MP | I82: 2560 × 1440 | J82: 1/2.8" CMOS | K82: 3–10 mm varifocal | L82: IR 40 m | M82: WDR 120 dB | N82: Analíticas Bosch | O82: H.265 / H.264 (Smart Encoding) | P82: Perfil S, T, G | Q82: E/S integrada | R82: 1 E / 1 S | S82: microSD 512 GB | T82: IP66 | U82: 802.3af | V82: 9 W máx | W82: -30 °C a +55 °C | X82: 240 × 90 × 90 mm | Y82: 1.1 kg | Z82: CE, FCC, UL | AA82: Exterior | AB82: 700 | AE82: Gama de entrada
... B110: 106 | C110: Bosch Security Systems | D110: Premium | E110: Alemania | F110: Multisensor / Panorámica | G110: FLEXIDOME IP multi 9000i (NDS-9004-X40) | H110: 48 MP (4× 12 MP) | I110: 4× 4000 × 3000 | J110: 4× 1/2.7" CMOS | K110: 4× varifocal integrada | L110: IR 20 m | M110: WDR | N110: Multidireccional 180° + IVA | O110: H.265 / H.264 (Smart Encoding) | P110: Perfil S, T, G | Q110: E/S integrada | R110: 1 E / 1 S | S110: microSD 512 GB | T110: IP66 / IK10 | U110: 802.3at | V110: 20 W máx | W110: -30 °C a +55 °C | X110: Ø 240 × 85 mm | Y110: 1.9 kg | Z110: CE, FCC, UL | AA110: Interior/Exterior | AB110: 8580 | AE110: Tope de gama — máxima especificación
B111: 107 | C111: Bosch Security Systems | D111: Premium | E111: Alemania | F111: Oculta (Pinhole) | G111: No disponible en portafolio | AE111: Bosch no ofrece cámara oculta; alternativa micro-discreta: FLEXIDOME IP micro 5000i
B112: 108 | C112: Bosch Security Systems | D112: Premium | E112: Alemania | F112: Térmica | G112: MIC IP thermal 7100i (35 mm) | H112: Térmico 384 × 288 | I112: 384 × 288 px | J112: Microbolómetro LWIR | K112: 35/60/95 mm (según versión) | L112: Detección térmica 1.2 km | M112: — | N112: PTZ térmico + analíticas perimetrales | O112: H.265 / H.264 (Smart Encoding) | P112: Perfil S, T, G | Q112: E/S integrada | R112: 1 E / 1 S | S112: microSD 512 GB | T112: IP66 / IK10 | U112: 802.3at | V112: 65 W máx | W112: -30 °C a +55 °C | X112: Ø 245 × 545 mm | Y112: 9.5 kg | Z112: CE, FCC, UL | AA112: Exterior | AB112: 5750 | AE112: Variante económica de la gama
B113: 109 | C113: Bosch Security Systems | D113: Premium | E113: Alemania | F113: Térmica | G113: MIC IP thermal 7100i (60 mm) | H113: Térmico 384 × 288 | I113: 384 × 288 px | J113: Microbolómetro LWIR | K113: 35/60/95 mm (según versión) | L113: Detección térmica 1.2 km | M113: — | N113: PTZ térmico + analíticas perimetrales | O113: H.265 / H.264 (Smart Encoding) | P113: Perfil S, T, G | Q113: E/S integrada | R113: 1 E / 1 S | S113: microSD 512 GB | T113: IP66 / IK10 | U113: 802.3at | V113: 65 W máx | W113: -30 °C a +55 °C | X113: Ø 245 × 545 mm | Y113: 9.5 kg | Z113: CE, FCC, UL | AA113: Exterior | AB113: 8625 | AE113: Gama de entrada
B114: 110 | C114: Bosch Security Systems | D114: Premium | E114: Alemania | F114: Térmica | G114: MIC IP thermal 7100i (95 mm) | H114: Térmico 640 × 480 | I114: 640 × 480 px | J114: Microbolómetro LWIR | K114: 35/60/95 mm (según versión) | L114: Detección térmica 1.2 km | M114: — | N114: PTZ térmico + analíticas perimetrales | O114: H.265 / H.264 (Smart Encoding) | P114: Perfil S, T, G | Q114: E/S integrada | R114: 1 E / 1 S | S114: microSD 512 GB | T114: IP66 / IK10 | U114: 802.3at | V114: 65 W máx | W114: -30 °C a +55 °C | X114: Ø 245 × 545 mm | Y114: 9.5 kg | Z114: CE, FCC, UL | AA114: Exterior | AB114: 11500 | AE114: PTZ térmico rotatorio 360°
B115: 111 | C115: Bosch Security Systems | D115: Premium | E115: Alemania | F115: Térmica | G115: MIC IP dynamic 7000i | H115: Térmico 640 × 480 | I115: 640 × 480 px | J115: Microbolómetro LWIR | K115: 35/60/95 mm (según versión) | L115: Detección térmica 1.2 km | M115: — | N115: PTZ térmico + analíticas perimetrales | O115: H.265 / H.264 (Smart Encoding) | P115: Perfil S, T, G | Q115: E/S integrada | R115: 1 E / 1 S | S115: microSD 512 GB | T115: IP66 / IK10 | U115: 802.3at | V115: 65 W máx | W115: -30 °C a +55 °C | X115: Ø 245 × 545 mm | Y115: 9.5 kg | Z115: CE, FCC, UL | AA115: Exterior | AB115: 17250 | AE115: Resolución y rendimiento mejorados
B116: 112 | C116: Bosch Security Systems | D116: Premium | E116: Alemania | F116: Térmica | G116: MIC IP fusion 9000i | H116: Térmico 640 × 480 | I116: 640 × 480 px | J116: Microbolómetro LWIR | K116: 35/60/95 mm (según versión) | L116: Detección térmica 1.2 km | M116: — | N116: PTZ térmico + analíticas perimetrales | O116: H.265 / H.264 (Smart Encoding) | P116: Perfil S, T, G | Q116: E/S integrada | R116: 1 E / 1 S | S116: microSD 512 GB | T116: IP66 / IK10 | U116: 802.3at | V116: 65 W máx | W116: -30 °C a +55 °C | X116: Ø 245 × 545 mm | Y116: 9.5 kg | Z116: CE, FCC, UL | AA116: Exterior | AB116: 25300 | AE116: Tope de gama — máxima especificación
B117: 113 | C117: Bosch Security Systems | D117: Premium | E117: Alemania | F117: LPR (Matrículas) | G117: DINION 7100i IR ANPR (8–32 mm) | H117: 2 MP | I117: 1920 × 1080 | J117: 1/2.8" CMOS | K117: 8–32 mm varifocal | L117: IR 40 m — obturador rápido | M117: WDR 120 dB | N117: ANPR vía Video Analytics (licencia) | O117: H.265 / H.264 (Smart Encoding) | P117: Perfil S, T, G | Q117: E/S integrada | R117: 1 E / 1 S | S117: microSD 512 GB | T117: IP66 | U117: 802.3af | V117: 10 W máx | W117: -30 °C a +55 °C | X117: 250 × 92 × 90 mm | Y117: 1.0 kg | Z117: CE, FCC, UL | AA117: Exterior | AB117: 525 | AE117: Variante económica de la gama
B118: 114 | C118: Bosch Security Systems | D118: Premium | E118: Alemania | F118: LPR (Matrículas) | G118: DINION 7100i IR ANPR (16–50 mm) | H118: 4 MP | I118: 2560 × 1440 | J118: 1/2.8" CMOS | K118: 8–32 mm varifocal | L118: IR 40 m — obturador rápido | M118: WDR 120 dB | N118: ANPR vía Video Analytics (licencia) | O118: H.265 / H.264 (Smart Encoding) | P118: Perfil S, T, G | Q118: E/S integrada | R118: 1 E / 1 S | S118: microSD 512 GB | T118: IP66 | U118: 802.3af | V118: 10 W máx | W118: -30 °C a +55 °C | X118: 250 × 92 × 90 mm | Y118: 1.0 kg | Z118: CE, FCC, UL | AA118: Exterior | AB118: 790 | AE118: Gama de entrada
B119: 115 | C119: Bosch Security Systems | D119: Premium | E119: Alemania | F119: LPR (Matrículas) | G119: DINION 7100i IR ANPR (35–80 mm) | H119: 8 MP (4K) | I119: 3840 × 2160 | J119: 1/2.8" CMOS | K119: 8–32 mm varifocal | L119: IR 40 m — obturador rápido | M119: WDR 120 dB | N119: ANPR vía Video Analytics (licencia) | O119: H.265 / H.264 (Smart Encoding) | P119: Perfil S, T, G | Q119: E/S integrada | R119: 1 E / 1 S | S119: microSD 512 GB | T119: IP66 | U119: 802.3af | V119: 10 W máx | W119: -30 °C a +55 °C | X119: 250 × 92 × 90 mm | Y119: 1.0 kg | Z119: CE, FCC, UL | AA119: Exterior | AB119: 1050 | AE119: Lectura de matrículas con VMS
B120: 116 | C120: Bosch Security Systems | D120: Premium | E120: Alemania | F120: LPR (Matrículas) | G120: FLEXIDOME 7100i IR ANPR (8–32 mm) | H120: 8 MP (4K) | I120: 3840 × 2160 | J120: 1/2.8" CMOS | K120: 8–32 mm varifocal | L120: IR 40 m — obturador rápido | M120: WDR 120 dB | N120: ANPR vía Video Analytics (licencia) | O120: H.265 / H.264 (Smart Encoding) | P120: Perfil S, T, G | Q120: E/S integrada | R120: 1 E / 1 S | S120: microSD 512 GB | T120: IP66 | U120: 802.3af | V120: 10 W máx | W120: -30 °C a +55 °C | X120: 250 × 92 × 90 mm | Y120: 1.0 kg | Z120: CE, FCC, UL | AA120: Exterior | AB120: 1575 | AE120: Resolución y rendimiento mejorados
B121: 117 | C121: Bosch Security Systems | D121: Premium | E121: Alemania | F121: LPR (Matrículas) | G121: AUTODOME 7000i ANPR | H121: 8 MP (4K) | I121: 3840 × 2160 | J121: 1/2.8" CMOS | K121: 8–32 mm varifocal | L121: IR 40 m — obturador rápido | M121: WDR 120 dB | N121: ANPR vía Video Analytics (licencia) | O121: H.265 / H.264 (Smart Encoding) | P121: Perfil S, T, G | Q121: E/S integrada | R121: 1 E / 1 S | S121: microSD 512 GB | T121: IP66 | U121: 802.3af | V121: 10 W máx | W121: -30 °C a +55 °C | X121: 250 × 92 × 90 mm | Y121: 1.0 kg | Z121: CE, FCC, UL | AA121: Exterior | AB121: 2310 | AE121: Tope de gama — máxima especificación
...

Sheet Equipamiento
B2: Base de Datos de Equipamiento — NVR · Almacenamiento · Switch PoE · UPS · Monitor · Rack · Cableado · Accesorios · Fuentes · VMS
B4: N° | C4: Categoría | D4: Marca | E4: Nivel | F4: Modelo | G4: Descripción | H4: Especificación Principal | I4: Características | J4: Compatibilidad / Integración | K4: Alimentación | L4: Montaje / Formato | M4: Dimensiones | N4: Peso | O4: Precio Ref. (USD) | P4: Proveedor | Q4: Stock | R4: Observaciones
B5: 1 | C5: NVR / DVR | D5: Axis Communications | E5: Premium | F5: AXIS S3008 Recorder | G5: NVR IP llave en mano para cámaras Axis y ONVIF | H5: 8 canales · HDD 2 TB incluido | I5: Sin configuración previa, H.265, HTTPS, actualizaciones automáticas | J5: Cámaras Axis + ONVIF S/T | K5: 100–240 VAC | L5: Escritorio / rack 1U | M5: 445 × 380 × 45 mm | N5: 4.1 kg | O5: 449 | R5: La opción más simple para proyectos pequeños Axis
B6: 2 | C6: NVR / DVR | D6: Hikvision | E6: Medio | F6: DS-7608NXI-K2/8P | G6: NVR AcuSense con PoE integrado | H6: 8 canales · 8 Puertos PoE · 2 bahías SATA | I6: H.265+, decodificación 8 MP, análisis AcuSearch (rostro/vehículo), HDMI 4K + VGA | J6: ONVIF (Perfil S) — cámaras de cualquier marca | K6: 100–240 VAC | L6: Rack 1U / escritorio | M6: 445 × 390 × 75 mm | N6: 4.0 kg | O6: 289 | R6: Estándar de la industria para instalaciones de 4–8 cámaras
B7: 3 | C7: NVR / DVR | D7: Hikvision | E7: Medio | F7: DS-7208HUHI-K2 | G7: DVR híbrido Turbo HD 5.0 | H7: 8 canales coaxiales + 4 IP · 2 bahías SATA | I7: HDTVI hasta 8 MP, audio sobre coaxial, compatible TVI/AHD/CVI/CVBS | J7: Cámaras analógicas HD + hasta 4 IP ONVIF | K7: 100–240 VAC | L7: Rack 1U / escritorio | M7: 380 × 320 × 48 mm | N7: 2.5 kg | O7: 139 | R7: Para modernizar sistemas coaxiales existentes
B8: 4 | C8: NVR / DVR | D8: Dahua Technology | E8: Medio | F8: NVR5216-16P-4KS2E | G8: NVR WizSense con PoE | H8: 16 canales · 16 PoE · 2 bahías SATA | I8: H.265+, SMD (detección inteligente de movimiento), ANPR opcional, HDMI+VGA | J8: ONVIF (Perfil S/T) | K8: 100–240 VAC | L8: Rack 1U / escritorio | M8: 440 × 410 × 75 mm | N8: 4.5 kg | O8: 519 | R8: Buena relación canales/PoE para proyectos medianos
B9: 5 | C9: NVR / DVR | D9: Uniview (UNV) | E9: Medio | F9: NVR302-16S-P16 | G9: NVR profesional con PoE | H9: 16 canales · 16 PoE · 2 bahías SATA | I9: H.265, Lighthouse (búsqueda por IA), almacenamiento en nube EZStation | J9: ONVIF (Perfil S/T/G) | K9: 100–240 VAC | L9: Rack 1U / escritorio | M9: 440 × 393 × 68 mm | N9: 4.2 kg | O9: 379 | R9: Interfaz EZStation/EZView muy valorada por integradores
B10: 6 | C10: NVR / DVR | D10: Hanwha Vision (Wisenet) | E10: Premium | F10: HRX-810-4TB | G10: DVR pentabrid con HDD preinstalado | H10: 8 canales analógicos + IP · 4 TB incluidos | I10: Soporta AHD/TVI/CVI/CVBS + IP, WiseStream, búsqueda inteligente | J10: Analógicos HD + IP ONVIF | K10: 100–240 VAC | L10: Escritorio / rack 1U | M10: 430 × 380 × 88 mm | N10: 3.8 kg | O10: 439 | R10: Incluye disco de 4 TB listo para grabar
B11: 7 | C11: NVR / DVR | D11: Reolink | E11: Económico | F11: RLN16-410 | G11: NVR PoE para cámaras Reolink/ONVIF | H11: 16 canales · 4 bahías SATA (sin HDD) | I11: H.264/H.265, acceso remoto Reolink App, sin análisis IA en el NVR | J11: Cámaras Reolink + RTSP/ONVIF limitado | K11: 100–240 VAC | L11: Escritorio / rack 1U | M11: 440 × 410 × 65 mm | N11: 3.6 kg | O11: 269 | R11: Comprar HDD aparte (ver categoría Almacenamiento)
B12: 8 | C12: NVR / DVR | D12: TP-Link VIGI | E12: Económico | F12: VIGI NVR1008H-8P | G12: NVR VIGI con PoE extendido | H12: 8 canales · 8 PoE · 1 bahía SATA | I12: H.265+, PoE hasta 250 m en modo extendido, VIGI Security Manager | J12: Cámaras VIGI + ONVIF | K12: 100–240 VAC | L12: Escritorio / rack 1U | M12: 315 × 240 × 45 mm | N12: 1.9 kg | O12: 159 | R12: Ideal para paquetes VIGI llave en mano
B13: 9 | C13: NVR / DVR | D13: HiLook (Hikvision) | E13: Económico | F13: NVR-208MH-C/8P | G13: NVR HiLook con PoE | H13: 8 canales · 8 PoE · 2 bahías SATA | I13: H.265+, AcuSearch simplificado, HDMI 4K | J13: ONVIF (Perfil S) — línea económica de Hikvision | K13: 100–240 VAC | L13: Rack 1U / escritorio | M13: 385 × 315 × 52 mm | N13: 3.0 kg | O13: 139 | R13: Equivalente económico del DS-7608NXI
B14: 10 | C14: NVR / DVR | D14: Imou (Dahua) | E14: Económico | F14: NVR1008H-08P | G14: NVR compacto Imou con PoE | H14: 8 canales · 8 PoE · 1 bahía SATA | I14: H.265+, app Imou Life, unidad SSD 2.5" soportada | J14: Cámaras Imou + ONVIF | K14: 100–240 VAC | L14: Escritorio | M14: 300 × 225 × 45 mm | N14: 1.6 kg | O14: 119 | R14: Para hogares y pequeñas oficinas con cámaras Imou
B15: 11 | C15: Almacenamiento (HDD) | D15: Seagate | E15: Medio | F15: SkyHawk AI 8 TB (ST8000VE001) | G15: Disco de vigilancia con soporte IA | H15: 8 TB · 550 TB/año de carga de trabajo | I15: ImagePerfect AI, hasta 32 flujos de IA, MTBF 1M h, RV (antivibración) | J15: NVR/DVR SATA III | K15: SATA 6 Gb/s | L15: Interno 3.5" | M15: 147 × 101.85 × 26.1 mm | N15: 680 g | O15: 189 | R15: Recomendado cuando el NVR ejecuta analíticas de IA
B16: 12 | C16: Almacenamiento (HDD) | D16: Western Digital | E16: Medio | F16: Purple Pro 8 TB (WD82PURP) | G16: Disco de vigilancia gama profesional | H16: 8 TB · 550 TB/año | I16: AllFrame AI (reduce pérdida de fotogramas), hasta 32 flujos IA, MTBF 1M h | J16: NVR/DVR SATA III | K16: SATA 6 Gb/s | L16: Interno 3.5" | M16: 147 × 101.6 × 26.1 mm | N16: 650 g | O16: 185 | R16: Alternativa directa al SkyHawk AI
... B66: 62 | C66: Software VMS | D66: Perspective Software | E66: Económico | F66: Blue Iris v5 (licencia) | G66: VMS ligero para Windows | H66: Hasta 64 cámaras · 1 licencia completa | I66: Grabación por movimiento/IA (CodeProject), app móvil, bajo costo de hardware | J66: Cámaras RTSP/ONVIF de cualquier marca | K66: PC Windows | L66: Licencia electrónica | M66: — | N66: — | O66: 70 | R66: Favorita DIY; requiere PC dedicado potente

Sheet Comparativa
B2: Comparativa por Tipo de Cámara — Modelos de Referencia
B5: 1. Domo
B6: Cámara compacta de techo o pared, discreta, para interiores y exteriores
B7: Especificación | C7: Axis Communications AXIS P3245-LVE | D7: Hikvision DS-2CD2131G0-I | E7: HiLook (Hikvision) IPC-D150H-MU
B8: Nivel | C8: Premium | D8: Medio | E8: Económico
B9: Resolución | C9: 4 MP | D9: 4 MP | E9: 4 MP
B10: Resolución Máx. | C10: 2560 × 1440 | D10: 2560 × 1440 | E10: 2560 × 1440
B11: Sensor | C11: 1/2.8" Sony Starvis | D11: 1/2.8" CMOS | E11: 1/2.7" CMOS
B12: Lente | C12: 3–9 mm varifocal P-Iris | D12: 2.8 mm fijo (4 mm opcional) | E12: 3.6 mm fijo
B13: Visión Nocturna | C13: OptimizedIR 40 m | D13: IR 30 m | E13: IR 30 m
B14: WDR | C14: Forensic WDR | D14: WDR 120 dB | E14: WDR 120 dB
B15: Analíticas IA | C15: AXIS Object Analytics | D15: EasyIP 4.0 — analíticas básicas | E15: Analíticas básicas (movimiento, cruce de línea)
B16: Audio | C16: E/S (según modelo) | D16: 1 E / 1 S (según modelo) | E16: Micrófono integrado (según modelo)
B17: Protección | C17: IP66 / IK10 | D17: IP66 | E17: IP66
B18: PoE | C18: 802.3af | D18: 802.3af | E18: 802.3af
... B20: Temp. Operación | C20: -30 °C a +50 °C | D20: -30 °C a +60 °C | E20: -30 °C a +60 °C
B21: Precio Ref. (USD) | C21: 1090 | D21: 95 | E21: 50
B23: 2. Domo Antivandálica
B24: Domo reforzado IK10 para ambientes con alto riesgo de vandalismo
B25: Especificación | C25: Bosch Security Systems FLEXIDOME IP outdoor 5000i (NDE-5502-AL) | D25: Dahua Technology DH-IPC-HDBW2431T1-AS-S2 | E25: TP-Link VIGI VIGI C450V
B26: Nivel | C26: Premium | D26: Medio | E26: Económico
B27: Resolución | C27: 4 MP | D27: 4 MP | E27: 4 MP
B28: Resolución Máx. | C28: 2560 × 1440 | D28: 2560 × 1440 | E28: 2560 × 1440
B29: Sensor | C29: 1/2.8" CMOS | D29: 1/2.8" CMOS | E29: 1/3" CMOS
B30: Lente | C30: 2.8–10 mm varifocal | D30: 2.7–13.5 mm varifocal | E30: 2.8–8 mm motorizada
B31: Visión Nocturna | C31: IR 30 m | D31: IR 50 m | E31: Full color — LED blanco 30 m
B32: WDR | C32: WDR 120 dB | D32: WDR 120 dB | E32: WDR
B33: Analíticas IA | C33: Analíticas Bosch (movimiento inteligente) | D33: IVS + analíticas | E33: Detección IA personas/vehículos
B34: Audio | C34: E/S integrada | D34: 1 E / 1 S (según modelo) | E34: Micrófono/altavoz integrado
B35: Protección | C35: IP66 / IK10 | D35: IK10 / IP67 | E35: IP66 / IK10
B36: PoE | C36: 802.3af | D36: 802.3af | E36: 802.3af
... B38: Temp. Operación | C38: -30 °C a +55 °C | D38: -30 °C a +60 °C | E38: -20 °C a +50 °C
B39: Precio Ref. (USD) | C39: 890 | D39: 145 | E39: 85
B41: 3. Bala
B42: Formato cilíndrico con soporte; mayor alcance IR, ideal para perímetros
B43: Especificación | C43: Axis Communications AXIS P1467-LE | D43: Hikvision DS-2CD2043G0-I | E43: Reolink RLC-820A
B44: Nivel | C44: Premium | D44: Medio | E44: Económico
B45: Resolución | C45: 4 MP | D45: 4 MP | E45: 4 MP
B46: Resolución Máx. | C46: 2560 × 1440 | D46: 2560 × 1440 | E46: 2560 × 1440
B47: Sensor | C47: 1/2.8" Sony Starvis | D47: 1/1.8" CMOS ColorVu | E47: 1/2.8" CMOS
...

Sheet Lista de Precios
B2: Lista de Precios / Cotización — Cámaras y Equipamiento
B4: Cliente:
B5: Proyecto:
B6: Fecha:
B7: Elaborado por:
